<?xml version="1.0" ?>
<!-- =================================================================================== -->
<!-- |    This document was autogenerated by xacro from cube.xacro                     | -->
<!-- |    EDITING THIS FILE BY HAND IS NOT RECOMMENDED                                 | -->
<!-- =================================================================================== -->
<!-- Revolute-Revolute Manipulator -->
<robot name="cdpr">
  <material name="black">
    <color rgba="0.0 0.0 0.0 1.0"/>
  </material>
  <material name="blue">
    <color rgba="0.0 0.0 0.8 1.0"/>
  </material>
  <material name="green">
    <color rgba="0.0 0.8 0.0 1.0"/>
  </material>
  <material name="grey">
    <color rgba="0.2 0.2 0.2 1.0"/>
  </material>
  <material name="orange">
    <color rgba="1.0 0.4235294117647059 0.0392156862745098 1.0"/>
  </material>
  <material name="brown">
    <color rgba="0.8705882352941177 0.8117647058823529 0.7647058823529411 1.0"/>
  </material>
  <material name="red">
    <color rgba="0.8 0.0 0.0 1.0"/>
  </material>
  <material name="white">
    <color rgba="1.0 1.0 1.0 1.0"/>
  </material>
  <!--Definition of the robot cables-->
  <link name="cable0">
    <collision>
      <origin rpy="-2.436024 0.575296 -1.353793" xyz="-0.792380 -0.792380 1.756272"/>
      <geometry>
        <cylinder length="3.4641016151377544" radius="0.005"/>
      </geometry>
    </collision>
    <visual>
      <origin rpy="-2.436024 0.575296 -1.353793" xyz="-0.792380 -0.792380 1.756272"/>
      <geometry>
        <cylinder length="3.4641016151377544" radius="0.005"/>
      </geometry>
      <material name="blue"/>
    </visual>
    <inertial>
      <origin rpy="-2.436024 0.575296 -1.353793" xyz="-0.792380 -0.792380 1.756272"/>
      <geometry>
        <cylinder length="3.4641016151377544" radius="0.005"/>
      </geometry>
      <inertia ixx="0.001" ixy="0" ixz="0" iyy="0.001" iyz="0" izz="0.001"/>
      <mass value="0.001"/>
    </inertial>
  </link>
  <link name="virt_X0">
    <inertial>
      <mass value="0.001"/>
      <inertia ixx="0.001" ixy="0" ixz="0" iyy="0.001" iyz="0" izz="0.001"/>
      <origin rpy="-2.436024 0.575296 -1.353793" xyz="-1.000000 -1.000000 2.000000"/>
    </inertial>
    <visual>
      <geometry>
        <box size="0.1 0.1 0.1"/>
      </geometry>
      <material name="blue"/>
    </visual>
  </link>
  <joint name="rev_X0" type="revolute">
    <origin rpy="-2.436024 0.575296 -1.353793" xyz="-1.000000 -1.000000 2.000000"/>
    <parent link="frame_1"/>
    <child link="virt_X0"/>
    <axis xyz="0.180647 -0.819353 -0.544084"/>
    <limit effort="10000" velocity="0.25"/>
    <limit damping="0.1"/>
  </joint>
  <link name="virt_Y0">
    <inertial>
      <origin rpy="-2.436024 0.575296 -1.353793" xyz="-1.000000 -1.000000 2.000000"/>
      <mass value="0.001"/>
      <inertia ixx="0.001" ixy="0" ixz="0" iyy="0.001" iyz="0" izz="0.001"/>
      <origin rpy="-2.436024 0.575296 -1.353793" xyz="-1.000000 -1.000000 2.000000"/>
    </inertial>
    <visual>
      <geometry>
        <box size="0.1 0.1 0.1"/>
      </geometry>
      <material name="blue"/>
    </visual>
  </link>
  <joint name="rev_Y0" type="revolute">
    <origin rpy="-2.436024 0.575296 -1.353793" xyz="0 0 0"/>
    <parent link="virt_X0"/>
    <child link="virt_Y0"/>
    <axis xyz="-0.819353 0.180647 -0.544084"/>
    <limit effort="10000" velocity="0.25"/>
    <limit damping="0.1"/>
  </joint>
  <joint name="joint_cable0" type="prismatic">
    <origin rpy="-2.436024 0.575296 -1.353793" xyz="-0.20762000000000003 -0.20762000000000003 0.24372799999999994"/>
    <parent link="virt_Y0"/>
    <child link="cable0"/>
    <axis xyz="-0.544084 -0.544084 0.638707"/>
    <limit effort="10000" lower="-1.7320508075688772" upper="1.7320508075688772" velocity="0.25"/>
    <limit damping="0.1"/>
  </joint>
  <link name="virt_Xpf0">
    <inertial>
      <origin rpy="-2.436024 0.575296 -1.353793" xyz="0.150000 0.150000 0.650000"/>
      <mass value="0.001"/>
      <inertia ixx="0.001" ixy="0" ixz="0" iyy="0.001" iyz="0" izz="0.001"/>
    </inertial>
    <visual>
      <origin rpy="-2.436024 0.575296 -1.353793" xyz="0.150000 0.150000 0.650000"/>
      <geometry>
        <box size="0.1 0.1 0.1"/>
      </geometry>
      <material name="blue"/>
      <origin rpy="-2.436024 0.575296 -1.353793" xyz="0.150000 0.150000 0.650000"/>
      <geometry>
        <box size="0.1 0.1 0.1"/>
      </geometry>
      <material name="blue"/>
    </visual>
  </link>
  <joint name="rev_Xpf0" type="revolute">
    <origin rpy="-2.436024 0.575296 -1.353793" xyz="0 0 0"/>
    <parent link="platform"/>
    <child link="virt_Xpf0"/>
    <axis xyz="1 0 0"/>
    <limit effort="10000" velocity="0.25"/>
    <limit damping="0.1"/>
  </joint>
  <link name="virt_Ypf0">
    <inertial>
      <origin rpy="-2.436024 0.575296 -1.353793" xyz="0.150000 0.150000 0.650000"/>
      <mass value="0.001"/>
      <inertia ixx="0.001" ixy="0" ixz="0" iyy="0.001" iyz="0" izz="0.001"/>
    </inertial>
  </link>
  <joint name="rev_Ypf0" type="revolute">
    <origin rpy="-2.436024 0.575296 -1.353793" xyz="0 0 0"/>
    <parent link="virt_Xpf0"/>
    <child link="virt_Ypf0"/>
    <axis xyz="0 1 0"/>
    <limit effort="10000" velocity="0.25"/>
    <limit damping="0.1"/>
  </joint>
  <joint name="rev_Zpf0" type="revolute">
    <origin rpy="-2.436024 0.575296 -1.353793" xyz="0.150000 0.150000 0.650000"/>
    <parent link="cable0"/>
    <child link="virt_Ypf0"/>
    <axis xyz="0 0 1"/>
    <limit effort="10000" velocity="0.25"/>
    <limit damping="0.1"/>
  </joint>
  <link name="cable1">
    <collision>
      <origin rpy="2.754717 0.667932 2.113659" xyz="-0.922769 0.963064 1.909338"/>
      <geometry>
        <cylinder length="3.4641016151377544" radius="0.005"/>
      </geometry>
    </collision>
    <visual>
      <origin rpy="2.754717 0.667932 2.113659" xyz="-0.922769 0.963064 1.909338"/>
      <geometry>
        <cylinder length="3.4641016151377544" radius="0.005"/>
      </geometry>
      <material name="blue"/>
    </visual>
    <inertial>
      <origin rpy="2.754717 0.667932 2.113659" xyz="-0.922769 0.963064 1.909338"/>
      <geometry>
        <cylinder length="3.4641016151377544" radius="0.005"/>
      </geometry>
      <inertia ixx="0.001" ixy="0" ixz="0" iyy="0.001" iyz="0" izz="0.001"/>
      <mass value="0.001"/>
    </inertial>
  </link>
  <link name="virt_X1">
    <inertial>
      <mass value="0.001"/>
      <inertia ixx="0.001" ixy="0" ixz="0" iyy="0.001" iyz="0" izz="0.001"/>
      <origin rpy="2.754717 0.667932 2.113659" xyz="-1.000000 1.000000 2.000000"/>
    </inertial>
    <visual>
      <geometry>
        <box size="0.1 0.1 0.1"/>
      </geometry>
      <material name="blue"/>
    </visual>
  </link>
  <joint name="rev_X1" type="revolute">
    <origin rpy="2.754717 0.667932 2.113659" xyz="-1.000000 1.000000 2.000000"/>
    <parent link="frame_1"/>
    <child link="virt_X1"/>
    <axis xyz="-0.405577 0.672232 -0.619364"/>
    <limit effort="10000" velocity="0.25"/>
    <limit damping="0.1"/>
  </joint>
  <link name="virt_Y1">
    <inertial>
      <origin rpy="2.754717 0.667932 2.113659" xyz="-1.000000 1.000000 2.000000"/>
      <mass value="0.001"/>
      <inertia ixx="0.001" ixy="0" ixz="0" iyy="0.001" iyz="0" izz="0.001"/>
      <origin rpy="2.754717 0.667932 2.113659" xyz="-1.000000 1.000000 2.000000"/>
    </inertial>
    <visual>
      <geometry>
        <box size="0.1 0.1 0.1"/>
      </geometry>
      <material name="blue"/>
    </visual>
  </link>
  <joint name="rev_Y1" type="revolute">
    <origin rpy="2.754717 0.667932 2.113659" xyz="0 0 0"/>
    <parent link="virt_X1"/>
    <child link="virt_Y1"/>
    <axis xyz="0.672232 0.678498 0.296217"/>
    <limit effort="10000" velocity="0.25"/>
    <limit damping="0.1"/>
  </joint>
  <joint name="joint_cable1" type="prismatic">
    <origin rpy="2.754717 0.667932 2.113659" xyz="-0.07723100000000005 0.03693599999999997 0.09066200000000002"/>
    <parent link="virt_Y1"/>
    <child link="cable1"/>
    <axis xyz="-0.619364 0.296217 0.727079"/>
    <limit effort="10000" lower="-1.7320508075688772" upper="1.7320508075688772" velocity="0.25"/>
    <limit damping="0.1"/>
  </joint>
  <link name="virt_Xpf1">
    <inertial>
      <origin rpy="2.754717 0.667932 2.113659" xyz="0.150000 0.450000 0.650000"/>
      <mass value="0.001"/>
      <inertia ixx="0.001" ixy="0" ixz="0" iyy="0.001" iyz="0" izz="0.001"/>
    </inertial>
    <visual>
      <origin rpy="2.754717 0.667932 2.113659" xyz="0.150000 0.450000 0.650000"/>
      <geometry>
        <box size="0.1 0.1 0.1"/>
      </geometry>
      <material name="blue"/>
      <origin rpy="2.754717 0.667932 2.113659" xyz="0.150000 0.450000 0.650000"/>
      <geometry>
        <box size="0.1 0.1 0.1"/>
      </geometry>
      <material name="blue"/>
    </visual>
  </link>
  <joint name="rev_Xpf1" type="revolute">
    <origin rpy="2.754717 0.667932 2.113659" xyz="0 0 0"/>
    <parent link="platform"/>
    <child link="virt_Xpf1"/>
    <axis xyz="1 0 0"/>
    <limit effort="10000" velocity="0.25"/>
    <limit damping="0.1"/>
  </joint>
  <link name="virt_Ypf1">
    <inertial>
      <origin rpy="2.754717 0.667932 2.113659" xyz="0.150000 0.450000 0.650000"/>
      <mass value="0.001"/>
      <inertia ixx="0.001" ixy="0" ixz="0" iyy="0.001" iyz="0" izz="0.001"/>
    </inertial>
  </link>
  <joint name="rev_Ypf1" type="revolute">
    <origin rpy="2.754717 0.667932 2.113659" xyz="0 0 0"/>
    <parent link="virt_Xpf1"/>
    <child link="virt_Ypf1"/>
    <axis xyz="0 1 0"/>
    <limit effort="10000" velocity="0.25"/>
    <limit damping="0.1"/>
  </joint>
  <joint name="rev_Zpf1" type="revolute">
    <origin rpy="2.754717 0.667932 2.113659" xyz="0.150000 0.450000 0.650000"/>
    <parent link="cable1"/>
    <child link="virt_Ypf1"/>
    <axis xyz="0 0 1"/>
    <limit effort="10000" velocity="0.25"/>
    <limit damping="0.1"/>
  </joint>
  <link name="cable2">
    <collision>
      <origin rpy="2.754717 -0.360783 -1.499377" xyz="1.061426 1.061426 2.150772"/>
      <geometry>
        <cylinder length="3.4641016151377544" radius="0.005"/>
      </geometry>
    </collision>
    <visual>
      <origin rpy="2.754717 -0.360783 -1.499377" xyz="1.061426 1.061426 2.150772"/>
      <geometry>
        <cylinder length="3.4641016151377544" radius="0.005"/>
      </geometry>
      <material name="blue"/>
    </visual>
    <inertial>
      <origin rpy="2.754717 -0.360783 -1.499377" xyz="1.061426 1.061426 2.150772"/>
      <geometry>
        <cylinder length="3.4641016151377544" radius="0.005"/>
      </geometry>
      <inertia ixx="0.001" ixy="0" ixz="0" iyy="0.001" iyz="0" izz="0.001"/>
      <mass value="0.001"/>
    </inertial>
  </link>
  <link name="virt_X2">
    <inertial>
      <mass value="0.001"/>
      <inertia ixx="0.001" ixy="0" ixz="0" iyy="0.001" iyz="0" izz="0.001"/>
      <origin rpy="2.754717 -0.360783 -1.499377" xyz="1.000000 1.000000 2.000000"/>
    </inertial>
    <visual>
      <geometry>
        <box size="0.1 0.1 0.1"/>
      </geometry>
      <material name="blue"/>
    </visual>
  </link>
  <joint name="rev_X2" type="revolute">
    <origin rpy="2.754717 -0.360783 -1.499377" xyz="1.000000 1.000000 2.000000"/>
    <parent link="frame_1"/>
    <child link="virt_X2"/>
    <axis xyz="0.066764 -0.933236 0.353007"/>
    <limit effort="10000" velocity="0.25"/>
    <limit damping="0.1"/>
  </joint>
  <link name="virt_Y2">
    <inertial>
      <origin rpy="2.754717 -0.360783 -1.499377" xyz="1.000000 1.000000 2.000000"/>
      <mass value="0.001"/>
      <inertia ixx="0.001" ixy="0" ixz="0" iyy="0.001" iyz="0" izz="0.001"/>
      <origin rpy="2.754717 -0.360783 -1.499377" xyz="1.000000 1.000000 2.000000"/>
    </inertial>
    <visual>
      <geometry>
        <box size="0.1 0.1 0.1"/>
      </geometry>
      <material name="blue"/>
    </visual>
  </link>
  <joint name="rev_Y2" type="revolute">
    <origin rpy="2.754717 -0.360783 -1.499377" xyz="0 0 0"/>
    <parent link="virt_X2"/>
    <child link="virt_Y2"/>
    <axis xyz="-0.933236 0.066764 0.353007"/>
    <limit effort="10000" velocity="0.25"/>
    <limit damping="0.1"/>
  </joint>
  <joint name="joint_cable2" type="prismatic">
    <origin rpy="2.754717 -0.360783 -1.499377" xyz="-0.06142599999999998 -0.06142599999999998 -0.1507719999999999"/>
    <parent link="virt_Y2"/>
    <child link="cable2"/>
    <axis xyz="0.353007 0.353007 0.866471"/>
    <limit effort="10000" lower="-1.7320508075688772" upper="1.7320508075688772" velocity="0.25"/>
    <limit damping="0.1"/>
  </joint>
  <link name="virt_Xpf2">
    <inertial>
      <origin rpy="2.754717 -0.360783 -1.499377" xyz="0.450000 0.450000 0.650000"/>
      <mass value="0.001"/>
      <inertia ixx="0.001" ixy="0" ixz="0" iyy="0.001" iyz="0" izz="0.001"/>
    </inertial>
    <visual>
      <origin rpy="2.754717 -0.360783 -1.499377" xyz="0.450000 0.450000 0.650000"/>
      <geometry>
        <box size="0.1 0.1 0.1"/>
      </geometry>
      <material name="blue"/>
      <origin rpy="2.754717 -0.360783 -1.499377" xyz="0.450000 0.450000 0.650000"/>
      <geometry>
        <box size="0.1 0.1 0.1"/>
      </geometry>
      <material name="blue"/>
    </visual>
  </link>
  <joint name="rev_Xpf2" type="revolute">
    <origin rpy="2.754717 -0.360783 -1.499377" xyz="0 0 0"/>
    <parent link="platform"/>
    <child link="virt_Xpf2"/>
    <axis xyz="1 0 0"/>
    <limit effort="10000" velocity="0.25"/>
    <limit damping="0.1"/>
  </joint>
  <link name="virt_Ypf2">
    <inertial>
      <origin rpy="2.754717 -0.360783 -1.499377" xyz="0.450000 0.450000 0.650000"/>
      <mass value="0.001"/>
      <inertia ixx="0.001" ixy="0" ixz="0" iyy="0.001" iyz="0" izz="0.001"/>
    </inertial>
  </link>
  <joint name="rev_Ypf2" type="revolute">
    <origin rpy="2.754717 -0.360783 -1.499377" xyz="0 0 0"/>
    <parent link="virt_Xpf2"/>
    <child link="virt_Ypf2"/>
    <axis xyz="0 1 0"/>
    <limit effort="10000" velocity="0.25"/>
    <limit damping="0.1"/>
  </joint>
  <joint name="rev_Zpf2" type="revolute">
    <origin rpy="2.754717 -0.360783 -1.499377" xyz="0.450000 0.450000 0.650000"/>
    <parent link="cable2"/>
    <child link="virt_Ypf2"/>
    <axis xyz="0 0 1"/>
    <limit effort="10000" velocity="0.25"/>
    <limit damping="0.1"/>
  </joint>
  <link name="cable3">
    <collision>
      <origin rpy="-2.436024 -0.300730 0.780760" xyz="0.963064 -0.922769 1.909338"/>
      <geometry>
        <cylinder length="3.4641016151377544" radius="0.005"/>
      </geometry>
    </collision>
    <visual>
      <origin rpy="-2.436024 -0.300730 0.780760" xyz="0.963064 -0.922769 1.909338"/>
      <geometry>
        <cylinder length="3.4641016151377544" radius="0.005"/>
      </geometry>
      <material name="blue"/>
    </visual>
    <inertial>
      <origin rpy="-2.436024 -0.300730 0.780760" xyz="0.963064 -0.922769 1.909338"/>
      <geometry>
        <cylinder length="3.4641016151377544" radius="0.005"/>
      </geometry>
      <inertia ixx="0.001" ixy="0" ixz="0" iyy="0.001" iyz="0" izz="0.001"/>
      <mass value="0.001"/>
    </inertial>
  </link>
  <link name="virt_X3">
    <inertial>
      <mass value="0.001"/>
      <inertia ixx="0.001" ixy="0" ixz="0" iyy="0.001" iyz="0" izz="0.001"/>
      <origin rpy="-2.436024 -0.300730 0.780760" xyz="1.000000 -1.000000 2.000000"/>
    </inertial>
    <visual>
      <geometry>
        <box size="0.1 0.1 0.1"/>
      </geometry>
      <material name="blue"/>
    </visual>
  </link>
  <joint name="rev_X3" type="revolute">
    <origin rpy="-2.436024 -0.300730 0.780760" xyz="1.000000 -1.000000 2.000000"/>
    <parent link="frame_1"/>
    <child link="virt_X3"/>
    <axis xyz="0.678498 0.672232 0.296217"/>
    <limit effort="10000" velocity="0.25"/>
    <limit damping="0.1"/>
  </joint>
  <link name="virt_Y3">
    <inertial>
      <origin rpy="-2.436024 -0.300730 0.780760" xyz="1.000000 -1.000000 2.000000"/>
      <mass value="0.001"/>
      <inertia ixx="0.001" ixy="0" ixz="0" iyy="0.001" iyz="0" izz="0.001"/>
      <origin rpy="-2.436024 -0.300730 0.780760" xyz="1.000000 -1.000000 2.000000"/>
    </inertial>
    <visual>
      <geometry>
        <box size="0.1 0.1 0.1"/>
      </geometry>
      <material name="blue"/>
    </visual>
  </link>
  <joint name="rev_Y3" type="revolute">
    <origin rpy="-2.436024 -0.300730 0.780760" xyz="0 0 0"/>
    <parent link="virt_X3"/>
    <child link="virt_Y3"/>
    <axis xyz="0.672232 -0.405577 -0.619364"/>
    <limit effort="10000" velocity="0.25"/>
    <limit damping="0.1"/>
  </joint>
  <joint name="joint_cable3" type="prismatic">
    <origin rpy="-2.436024 -0.300730 0.780760" xyz="0.03693599999999997 -0.07723100000000005 0.09066200000000002"/>
    <parent link="virt_Y3"/>
    <child link="cable3"/>
    <axis xyz="0.296217 -0.619364 0.727079"/>
    <limit effort="10000" lower="-1.7320508075688772" upper="1.7320508075688772" velocity="0.25"/>
    <limit damping="0.1"/>
  </joint>
  <link name="virt_Xpf3">
    <inertial>
      <origin rpy="-2.436024 -0.300730 0.780760" xyz="0.450000 0.150000 0.650000"/>
      <mass value="0.001"/>
      <inertia ixx="0.001" ixy="0" ixz="0" iyy="0.001" iyz="0" izz="0.001"/>
    </inertial>
    <visual>
      <origin rpy="-2.436024 -0.300730 0.780760" xyz="0.450000 0.150000 0.650000"/>
      <geometry>
        <box size="0.1 0.1 0.1"/>
      </geometry>
      <material name="blue"/>
      <origin rpy="-2.436024 -0.300730 0.780760" xyz="0.450000 0.150000 0.650000"/>
      <geometry>
        <box size="0.1 0.1 0.1"/>
      </geometry>
      <material name="blue"/>
    </visual>
  </link>
  <joint name="rev_Xpf3" type="revolute">
    <origin rpy="-2.436024 -0.300730 0.780760" xyz="0 0 0"/>
    <parent link="platform"/>
    <child link="virt_Xpf3"/>
    <axis xyz="1 0 0"/>
    <limit effort="10000" velocity="0.25"/>
    <limit damping="0.1"/>
  </joint>
  <link name="virt_Ypf3">
    <inertial>
      <origin rpy="-2.436024 -0.300730 0.780760" xyz="0.450000 0.150000 0.650000"/>
      <mass value="0.001"/>
      <inertia ixx="0.001" ixy="0" ixz="0" iyy="0.001" iyz="0" izz="0.001"/>
    </inertial>
  </link>
  <joint name="rev_Ypf3" type="revolute">
    <origin rpy="-2.436024 -0.300730 0.780760" xyz="0 0 0"/>
    <parent link="virt_Xpf3"/>
    <child link="virt_Ypf3"/>
    <axis xyz="0 1 0"/>
    <limit effort="10000" velocity="0.25"/>
    <limit damping="0.1"/>
  </joint>
  <joint name="rev_Zpf3" type="revolute">
    <origin rpy="-2.436024 -0.300730 0.780760" xyz="0.450000 0.150000 0.650000"/>
    <parent link="cable3"/>
    <child link="virt_Ypf3"/>
    <axis xyz="0 0 1"/>
    <limit effort="10000" velocity="0.25"/>
    <limit damping="0.1"/>
  </joint>
  <link name="cable4">
    <collision>
      <origin rpy="-1.275355 0.763259 -0.578033" xyz="-1.047332 -1.047332 -0.014405"/>
      <geometry>
        <cylinder length="3.4641016151377544" radius="0.005"/>
      </geometry>
    </collision>
    <visual>
      <origin rpy="-1.275355 0.763259 -0.578033" xyz="-1.047332 -1.047332 -0.014405"/>
      <geometry>
        <cylinder length="3.4641016151377544" radius="0.005"/>
      </geometry>
      <material name="blue"/>
    </visual>
    <inertial>
      <origin rpy="-1.275355 0.763259 -0.578033" xyz="-1.047332 -1.047332 -0.014405"/>
      <geometry>
        <cylinder length="3.4641016151377544" radius="0.005"/>
      </geometry>
      <inertia ixx="0.001" ixy="0" ixz="0" iyy="0.001" iyz="0" izz="0.001"/>
      <mass value="0.001"/>
    </inertial>
  </link>
  <link name="virt_X4">
    <inertial>
      <mass value="0.001"/>
      <inertia ixx="0.001" ixy="0" ixz="0" iyy="0.001" iyz="0" izz="0.001"/>
      <origin rpy="-1.275355 0.763259 -0.578033" xyz="-1.000000 -1.000000 0.000000"/>
    </inertial>
    <visual>
      <geometry>
        <box size="0.1 0.1 0.1"/>
      </geometry>
      <material name="blue"/>
    </visual>
  </link>
  <joint name="rev_X4" type="revolute">
    <origin rpy="-1.275355 0.763259 -0.578033" xyz="-1.000000 -1.000000 0.000000"/>
    <parent link="frame_1"/>
    <child link="virt_X4"/>
    <axis xyz="0.605195 -0.394805 -0.691280"/>
    <limit effort="10000" velocity="0.25"/>
    <limit damping="0.1"/>
  </joint>
  <link name="virt_Y4">
    <inertial>
      <origin rpy="-1.275355 0.763259 -0.578033" xyz="-1.000000 -1.000000 0.000000"/>
      <mass value="0.001"/>
      <inertia ixx="0.001" ixy="0" ixz="0" iyy="0.001" iyz="0" izz="0.001"/>
      <origin rpy="-1.275355 0.763259 -0.578033" xyz="-1.000000 -1.000000 0.000000"/>
    </inertial>
    <visual>
      <geometry>
        <box size="0.1 0.1 0.1"/>
      </geometry>
      <material name="blue"/>
    </visual>
  </link>
  <joint name="rev_Y4" type="revolute">
    <origin rpy="-1.275355 0.763259 -0.578033" xyz="0 0 0"/>
    <parent link="virt_X4"/>
    <child link="virt_Y4"/>
    <axis xyz="-0.394805 0.605195 -0.691280"/>
    <limit effort="10000" velocity="0.25"/>
    <limit damping="0.1"/>
  </joint>
  <joint name="joint_cable4" type="prismatic">
    <origin rpy="-1.275355 0.763259 -0.578033" xyz="0.04733199999999993 0.04733199999999993 0.014405"/>
    <parent link="virt_Y4"/>
    <child link="cable4"/>
    <axis xyz="-0.691280 -0.691280 -0.210390"/>
    <limit effort="10000" lower="-1.7320508075688772" upper="1.7320508075688772" velocity="0.25"/>
    <limit damping="0.1"/>
  </joint>
  <link name="virt_Xpf4">
    <inertial>
      <origin rpy="-1.275355 0.763259 -0.578033" xyz="0.150000 0.150000 0.350000"/>
      <mass value="0.001"/>
      <inertia ixx="0.001" ixy="0" ixz="0" iyy="0.001" iyz="0" izz="0.001"/>
    </inertial>
    <visual>
      <origin rpy="-1.275355 0.763259 -0.578033" xyz="0.150000 0.150000 0.350000"/>
      <geometry>
        <box size="0.1 0.1 0.1"/>
      </geometry>
      <material name="blue"/>
      <origin rpy="-1.275355 0.763259 -0.578033" xyz="0.150000 0.150000 0.350000"/>
      <geometry>
        <box size="0.1 0.1 0.1"/>
      </geometry>
      <material name="blue"/>
    </visual>
  </link>
  <joint name="rev_Xpf4" type="revolute">
    <origin rpy="-1.275355 0.763259 -0.578033" xyz="0 0 0"/>
    <parent link="platform"/>
    <child link="virt_Xpf4"/>
    <axis xyz="1 0 0"/>
    <limit effort="10000" velocity="0.25"/>
    <limit damping="0.1"/>
  </joint>
  <link name="virt_Ypf4">
    <inertial>
      <origin rpy="-1.275355 0.763259 -0.578033" xyz="0.150000 0.150000 0.350000"/>
      <mass value="0.001"/>
      <inertia ixx="0.001" ixy="0" ixz="0" iyy="0.001" iyz="0" izz="0.001"/>
    </inertial>
  </link>
  <joint name="rev_Ypf4" type="revolute">
    <origin rpy="-1.275355 0.763259 -0.578033" xyz="0 0 0"/>
    <parent link="virt_Xpf4"/>
    <child link="virt_Ypf4"/>
    <axis xyz="0 1 0"/>
    <limit effort="10000" velocity="0.25"/>
    <limit damping="0.1"/>
  </joint>
  <joint name="rev_Zpf4" type="revolute">
    <origin rpy="-1.275355 0.763259 -0.578033" xyz="0.150000 0.150000 0.350000"/>
    <parent link="cable4"/>
    <child link="virt_Ypf4"/>
    <axis xyz="0 0 1"/>
    <limit effort="10000" velocity="0.25"/>
    <limit damping="0.1"/>
  </joint>
  <link name="cable5">
    <collision>
      <origin rpy="1.004067 1.055080 0.619089" xyz="-1.356780 1.170634 -0.108585"/>
      <geometry>
        <cylinder length="3.4641016151377544" radius="0.005"/>
      </geometry>
    </collision>
    <visual>
      <origin rpy="1.004067 1.055080 0.619089" xyz="-1.356780 1.170634 -0.108585"/>
      <geometry>
        <cylinder length="3.4641016151377544" radius="0.005"/>
      </geometry>
      <material name="blue"/>
    </visual>
    <inertial>
      <origin rpy="1.004067 1.055080 0.619089" xyz="-1.356780 1.170634 -0.108585"/>
      <geometry>
        <cylinder length="3.4641016151377544" radius="0.005"/>
      </geometry>
      <inertia ixx="0.001" ixy="0" ixz="0" iyy="0.001" iyz="0" izz="0.001"/>
      <mass value="0.001"/>
    </inertial>
  </link>
  <link name="virt_X5">
    <inertial>
      <mass value="0.001"/>
      <inertia ixx="0.001" ixy="0" ixz="0" iyy="0.001" iyz="0" izz="0.001"/>
      <origin rpy="1.004067 1.055080 0.619089" xyz="-1.000000 1.000000 0.000000"/>
    </inertial>
    <visual>
      <geometry>
        <box size="0.1 0.1 0.1"/>
      </geometry>
      <material name="blue"/>
    </visual>
  </link>
  <joint name="rev_X5" type="revolute">
    <origin rpy="1.004067 1.055080 0.619089" xyz="-1.000000 1.000000 0.000000"/>
    <parent link="frame_1"/>
    <child link="virt_X5"/>
    <axis xyz="0.401631 0.286176 -0.869940"/>
    <limit effort="10000" velocity="0.25"/>
    <limit damping="0.1"/>
  </joint>
  <link name="virt_Y5">
    <inertial>
      <origin rpy="1.004067 1.055080 0.619089" xyz="-1.000000 1.000000 0.000000"/>
      <mass value="0.001"/>
      <inertia ixx="0.001" ixy="0" ixz="0" iyy="0.001" iyz="0" izz="0.001"/>
      <origin rpy="1.004067 1.055080 0.619089" xyz="-1.000000 1.000000 0.000000"/>
    </inertial>
    <visual>
      <geometry>
        <box size="0.1 0.1 0.1"/>
      </geometry>
      <material name="blue"/>
    </visual>
  </link>
  <joint name="rev_Y5" type="revolute">
    <origin rpy="1.004067 1.055080 0.619089" xyz="0 0 0"/>
    <parent link="virt_X5"/>
    <child link="virt_Y5"/>
    <axis xyz="0.286176 0.863133 0.416058"/>
    <limit effort="10000" velocity="0.25"/>
    <limit damping="0.1"/>
  </joint>
  <joint name="joint_cable5" type="prismatic">
    <origin rpy="1.004067 1.055080 0.619089" xyz="0.3567800000000001 -0.17063399999999995 0.108585"/>
    <parent link="virt_Y5"/>
    <child link="cable5"/>
    <axis xyz="-0.869940 0.416058 -0.264764"/>
    <limit effort="10000" lower="-1.7320508075688772" upper="1.7320508075688772" velocity="0.25"/>
    <limit damping="0.1"/>
  </joint>
  <link name="virt_Xpf5">
    <inertial>
      <origin rpy="1.004067 1.055080 0.619089" xyz="0.150000 0.450000 0.350000"/>
      <mass value="0.001"/>
      <inertia ixx="0.001" ixy="0" ixz="0" iyy="0.001" iyz="0" izz="0.001"/>
    </inertial>
    <visual>
      <origin rpy="1.004067 1.055080 0.619089" xyz="0.150000 0.450000 0.350000"/>
      <geometry>
        <box size="0.1 0.1 0.1"/>
      </geometry>
      <material name="blue"/>
      <origin rpy="1.004067 1.055080 0.619089" xyz="0.150000 0.450000 0.350000"/>
      <geometry>
        <box size="0.1 0.1 0.1"/>
      </geometry>
      <material name="blue"/>
    </visual>
  </link>
  <joint name="rev_Xpf5" type="revolute">
    <origin rpy="1.004067 1.055080 0.619089" xyz="0 0 0"/>
    <parent link="platform"/>
    <child link="virt_Xpf5"/>
    <axis xyz="1 0 0"/>
    <limit effort="10000" velocity="0.25"/>
    <limit damping="0.1"/>
  </joint>
  <link name="virt_Ypf5">
    <inertial>
      <origin rpy="1.004067 1.055080 0.619089" xyz="0.150000 0.450000 0.350000"/>
      <mass value="0.001"/>
      <inertia ixx="0.001" ixy="0" ixz="0" iyy="0.001" iyz="0" izz="0.001"/>
    </inertial>
  </link>
  <joint name="rev_Ypf5" type="revolute">
    <origin rpy="1.004067 1.055080 0.619089" xyz="0 0 0"/>
    <parent link="virt_Xpf5"/>
    <child link="virt_Ypf5"/>
    <axis xyz="0 1 0"/>
    <limit effort="10000" velocity="0.25"/>
    <limit damping="0.1"/>
  </joint>
  <joint name="rev_Zpf5" type="revolute">
    <origin rpy="1.004067 1.055080 0.619089" xyz="0.150000 0.450000 0.350000"/>
    <parent link="cable5"/>
    <child link="virt_Ypf5"/>
    <axis xyz="0 0 1"/>
    <limit effort="10000" velocity="0.25"/>
    <limit damping="0.1"/>
  </joint>
  <link name="cable6">
    <collision>
      <origin rpy="1.004067 -0.700803 -0.396004" xyz="1.566881 1.566881 -0.360742"/>
      <geometry>
        <cylinder length="3.4641016151377544" radius="0.005"/>
      </geometry>
    </collision>
    <visual>
      <origin rpy="1.004067 -0.700803 -0.396004" xyz="1.566881 1.566881 -0.360742"/>
      <geometry>
        <cylinder length="3.4641016151377544" radius="0.005"/>
      </geometry>
      <material name="blue"/>
    </visual>
    <inertial>
      <origin rpy="1.004067 -0.700803 -0.396004" xyz="1.566881 1.566881 -0.360742"/>
      <geometry>
        <cylinder length="3.4641016151377544" radius="0.005"/>
      </geometry>
      <inertia ixx="0.001" ixy="0" ixz="0" iyy="0.001" iyz="0" izz="0.001"/>
      <mass value="0.001"/>
    </inertial>
  </link>
  <link name="virt_X6">
    <inertial>
      <mass value="0.001"/>
      <inertia ixx="0.001" ixy="0" ixz="0" iyy="0.001" iyz="0" izz="0.001"/>
      <origin rpy="1.004067 -0.700803 -0.396004" xyz="1.000000 1.000000 0.000000"/>
    </inertial>
    <visual>
      <geometry>
        <box size="0.1 0.1 0.1"/>
      </geometry>
      <material name="blue"/>
    </visual>
  </link>
  <joint name="rev_X6" type="revolute">
    <origin rpy="1.004067 -0.700803 -0.396004" xyz="1.000000 1.000000 0.000000"/>
    <parent link="frame_1"/>
    <child link="virt_X6"/>
    <axis xyz="0.705174 -0.294826 0.644831"/>
    <limit effort="10000" velocity="0.25"/>
    <limit damping="0.1"/>
  </joint>
  <link name="virt_Y6">
    <inertial>
      <origin rpy="1.004067 -0.700803 -0.396004" xyz="1.000000 1.000000 0.000000"/>
      <mass value="0.001"/>
      <inertia ixx="0.001" ixy="0" ixz="0" iyy="0.001" iyz="0" izz="0.001"/>
      <origin rpy="1.004067 -0.700803 -0.396004" xyz="1.000000 1.000000 0.000000"/>
    </inertial>
    <visual>
      <geometry>
        <box size="0.1 0.1 0.1"/>
      </geometry>
      <material name="blue"/>
    </visual>
  </link>
  <joint name="rev_Y6" type="revolute">
    <origin rpy="1.004067 -0.700803 -0.396004" xyz="0 0 0"/>
    <parent link="virt_X6"/>
    <child link="virt_Y6"/>
    <axis xyz="-0.294826 0.705174 0.644831"/>
    <limit effort="10000" velocity="0.25"/>
    <limit damping="0.1"/>
  </joint>
  <joint name="joint_cable6" type="prismatic">
    <origin rpy="1.004067 -0.700803 -0.396004" xyz="-0.566881 -0.566881 0.360742"/>
    <parent link="virt_Y6"/>
    <child link="cable6"/>
    <axis xyz="0.644831 0.644831 -0.410347"/>
    <limit effort="10000" lower="-1.7320508075688772" upper="1.7320508075688772" velocity="0.25"/>
    <limit damping="0.1"/>
  </joint>
  <link name="virt_Xpf6">
    <inertial>
      <origin rpy="1.004067 -0.700803 -0.396004" xyz="0.450000 0.450000 0.350000"/>
      <mass value="0.001"/>
      <inertia ixx="0.001" ixy="0" ixz="0" iyy="0.001" iyz="0" izz="0.001"/>
    </inertial>
    <visual>
      <origin rpy="1.004067 -0.700803 -0.396004" xyz="0.450000 0.450000 0.350000"/>
      <geometry>
        <box size="0.1 0.1 0.1"/>
      </geometry>
      <material name="blue"/>
      <origin rpy="1.004067 -0.700803 -0.396004" xyz="0.450000 0.450000 0.350000"/>
      <geometry>
        <box size="0.1 0.1 0.1"/>
      </geometry>
      <material name="blue"/>
    </visual>
  </link>
  <joint name="rev_Xpf6" type="revolute">
    <origin rpy="1.004067 -0.700803 -0.396004" xyz="0 0 0"/>
    <parent link="platform"/>
    <child link="virt_Xpf6"/>
    <axis xyz="1 0 0"/>
    <limit effort="10000" velocity="0.25"/>
    <limit damping="0.1"/>
  </joint>
  <link name="virt_Ypf6">
    <inertial>
      <origin rpy="1.004067 -0.700803 -0.396004" xyz="0.450000 0.450000 0.350000"/>
      <mass value="0.001"/>
      <inertia ixx="0.001" ixy="0" ixz="0" iyy="0.001" iyz="0" izz="0.001"/>
    </inertial>
  </link>
  <joint name="rev_Ypf6" type="revolute">
    <origin rpy="1.004067 -0.700803 -0.396004" xyz="0 0 0"/>
    <parent link="virt_Xpf6"/>
    <child link="virt_Ypf6"/>
    <axis xyz="0 1 0"/>
    <limit effort="10000" velocity="0.25"/>
    <limit damping="0.1"/>
  </joint>
  <joint name="rev_Zpf6" type="revolute">
    <origin rpy="1.004067 -0.700803 -0.396004" xyz="0.450000 0.450000 0.350000"/>
    <parent link="cable6"/>
    <child link="virt_Ypf6"/>
    <axis xyz="0 0 1"/>
    <limit effort="10000" velocity="0.25"/>
    <limit damping="0.1"/>
  </joint>
  <link name="cable7">
    <collision>
      <origin rpy="-1.275355 -0.429106 0.320149" xyz="1.170634 -1.356780 -0.108585"/>
      <geometry>
        <cylinder length="3.4641016151377544" radius="0.005"/>
      </geometry>
    </collision>
    <visual>
      <origin rpy="-1.275355 -0.429106 0.320149" xyz="1.170634 -1.356780 -0.108585"/>
      <geometry>
        <cylinder length="3.4641016151377544" radius="0.005"/>
      </geometry>
      <material name="blue"/>
    </visual>
    <inertial>
      <origin rpy="-1.275355 -0.429106 0.320149" xyz="1.170634 -1.356780 -0.108585"/>
      <geometry>
        <cylinder length="3.4641016151377544" radius="0.005"/>
      </geometry>
      <inertia ixx="0.001" ixy="0" ixz="0" iyy="0.001" iyz="0" izz="0.001"/>
      <mass value="0.001"/>
    </inertial>
  </link>
  <link name="virt_X7">
    <inertial>
      <mass value="0.001"/>
      <inertia ixx="0.001" ixy="0" ixz="0" iyy="0.001" iyz="0" izz="0.001"/>
      <origin rpy="-1.275355 -0.429106 0.320149" xyz="1.000000 -1.000000 0.000000"/>
    </inertial>
    <visual>
      <geometry>
        <box size="0.1 0.1 0.1"/>
      </geometry>
      <material name="blue"/>
    </visual>
  </link>
  <joint name="rev_X7" type="revolute">
    <origin rpy="-1.275355 -0.429106 0.320149" xyz="1.000000 -1.000000 0.000000"/>
    <parent link="frame_1"/>
    <child link="virt_X7"/>
    <axis xyz="0.863133 0.286176 0.416058"/>
    <limit effort="10000" velocity="0.25"/>
    <limit damping="0.1"/>
  </joint>
  <link name="virt_Y7">
    <inertial>
      <origin rpy="-1.275355 -0.429106 0.320149" xyz="1.000000 -1.000000 0.000000"/>
      <mass value="0.001"/>
      <inertia ixx="0.001" ixy="0" ixz="0" iyy="0.001" iyz="0" izz="0.001"/>
      <origin rpy="-1.275355 -0.429106 0.320149" xyz="1.000000 -1.000000 0.000000"/>
    </inertial>
    <visual>
      <geometry>
        <box size="0.1 0.1 0.1"/>
      </geometry>
      <material name="blue"/>
    </visual>
  </link>
  <joint name="rev_Y7" type="revolute">
    <origin rpy="-1.275355 -0.429106 0.320149" xyz="0 0 0"/>
    <parent link="virt_X7"/>
    <child link="virt_Y7"/>
    <axis xyz="0.286176 0.401631 -0.869940"/>
    <limit effort="10000" velocity="0.25"/>
    <limit damping="0.1"/>
  </joint>
  <joint name="joint_cable7" type="prismatic">
    <origin rpy="-1.275355 -0.429106 0.320149" xyz="-0.17063399999999995 0.3567800000000001 0.108585"/>
    <parent link="virt_Y7"/>
    <child link="cable7"/>
    <axis xyz="0.416058 -0.869940 -0.264764"/>
    <limit effort="10000" lower="-1.7320508075688772" upper="1.7320508075688772" velocity="0.25"/>
    <limit damping="0.1"/>
  </joint>
  <link name="virt_Xpf7">
    <inertial>
      <origin rpy="-1.275355 -0.429106 0.320149" xyz="0.450000 0.150000 0.350000"/>
      <mass value="0.001"/>
      <inertia ixx="0.001" ixy="0" ixz="0" iyy="0.001" iyz="0" izz="0.001"/>
    </inertial>
    <visual>
      <origin rpy="-1.275355 -0.429106 0.320149" xyz="0.450000 0.150000 0.350000"/>
      <geometry>
        <box size="0.1 0.1 0.1"/>
      </geometry>
      <material name="blue"/>
      <origin rpy="-1.275355 -0.429106 0.320149" xyz="0.450000 0.150000 0.350000"/>
      <geometry>
        <box size="0.1 0.1 0.1"/>
      </geometry>
      <material name="blue"/>
    </visual>
  </link>
  <joint name="rev_Xpf7" type="revolute">
    <origin rpy="-1.275355 -0.429106 0.320149" xyz="0 0 0"/>
    <parent link="platform"/>
    <child link="virt_Xpf7"/>
    <axis xyz="1 0 0"/>
    <limit effort="10000" velocity="0.25"/>
    <limit damping="0.1"/>
  </joint>
  <link name="virt_Ypf7">
    <inertial>
      <origin rpy="-1.275355 -0.429106 0.320149" xyz="0.450000 0.150000 0.350000"/>
      <mass value="0.001"/>
      <inertia ixx="0.001" ixy="0" ixz="0" iyy="0.001" iyz="0" izz="0.001"/>
    </inertial>
  </link>
  <joint name="rev_Ypf7" type="revolute">
    <origin rpy="-1.275355 -0.429106 0.320149" xyz="0 0 0"/>
    <parent link="virt_Xpf7"/>
    <child link="virt_Ypf7"/>
    <axis xyz="0 1 0"/>
    <limit effort="10000" velocity="0.25"/>
    <limit damping="0.1"/>
  </joint>
  <joint name="rev_Zpf7" type="revolute">
    <origin rpy="-1.275355 -0.429106 0.320149" xyz="0.450000 0.150000 0.350000"/>
    <parent link="cable7"/>
    <child link="virt_Ypf7"/>
    <axis xyz="0 0 1"/>
    <limit effort="10000" velocity="0.25"/>
    <limit damping="0.1"/>
  </joint>
  <!-- Used for fixing robot to Gazebo 'base_link' -->
  <link name="world"/>
  <joint name="fixed" type="fixed">
    <parent link="world"/>
    <child link="frame_1"/>
  </joint>
  <joint name="float" type="floating">
    <parent link="world"/>
    <child link="platform"/>
  </joint>
  <!-- Base Link -->
  <link name="frame_1">
    <collision>
      <origin rpy="0 0 0" xyz="-1.0 -1.0 1.0"/>
      <geometry>
        <cylinder length="2" radius="0.02"/>
      </geometry>
    </collision>
    <visual>
      <origin rpy="0 0 0" xyz="-1.0 -1.0 1.0"/>
      <geometry>
        <cylinder length="2" radius="0.02"/>
      </geometry>
      <material name="orange"/>
    </visual>
    <inertial>
      <origin rpy="0 0 0" xyz="-1.0 -1.0 1.0"/>
      <mass value="10000"/>
      <inertia ixx="10000" ixy="0.0" ixz="0.0" iyy="10000" iyz="0.0" izz="10000"/>
    </inertial>
  </link>
  <link name="frame_2">
    <collision>
      <origin rpy="1.5707963267948966 0 0" xyz="-1.0 0 0"/>
      <geometry>
        <cylinder length="2" radius="0.02"/>
      </geometry>
    </collision>
    <visual>
      <origin rpy="1.5707963267948966 0 0" xyz="-1.0 0 0"/>
      <geometry>
        <cylinder length="2" radius="0.02"/>
      </geometry>
      <material name="orange"/>
    </visual>
    <inertial>
      <origin rpy="1.5707963267948966 0 0" xyz="-1.0 0 0"/>
      <mass value="10000"/>
      <inertia ixx="10000" ixy="0.0" ixz="0.0" iyy="10000" iyz="0.0" izz="10000"/>
    </inertial>
  </link>
  <link name="frame_3">
    <collision>
      <origin rpy="0 1.5707963267948966 0" xyz="0 -1.0 0"/>
      <geometry>
        <cylinder length="2" radius="0.02"/>
      </geometry>
    </collision>
    <visual>
      <origin rpy="0 1.5707963267948966 0" xyz="0 -1.0 0"/>
      <geometry>
        <cylinder length="2" radius="0.02"/>
      </geometry>
      <material name="orange"/>
    </visual>
    <inertial>
      <origin rpy="0 1.5707963267948966 0" xyz="0 -1.0 0"/>
      <mass value="10000"/>
      <inertia ixx="10000" ixy="0.0" ixz="0.0" iyy="10000" iyz="0.0" izz="10000"/>
    </inertial>
  </link>
  <link name="frame_4">
    <collision>
      <origin rpy="0 0 0" xyz="-1.0 1.0 1.0"/>
      <geometry>
        <cylinder length="2" radius="0.02"/>
      </geometry>
    </collision>
    <visual>
      <origin rpy="0 0 0" xyz="-1.0 1.0 1.0"/>
      <geometry>
        <cylinder length="2" radius="0.02"/>
      </geometry>
      <material name="orange"/>
    </visual>
    <inertial>
      <origin rpy="0 0 0" xyz="-1.0 1.0 1.0"/>
      <mass value="10000"/>
      <inertia ixx="10000" ixy="0.0" ixz="0.0" iyy="10000" iyz="0.0" izz="10000"/>
    </inertial>
  </link>
  <link name="frame_5">
    <collision>
      <origin rpy="0 0 0" xyz="1.0 1.0 1.0"/>
      <geometry>
        <cylinder length="2" radius="0.02"/>
      </geometry>
    </collision>
    <visual>
      <origin rpy="0 0 0" xyz="1.0 1.0 1.0"/>
      <geometry>
        <cylinder length="2" radius="0.02"/>
      </geometry>
      <material name="orange"/>
    </visual>
    <inertial>
      <origin rpy="0 0 0" xyz="1.0 1.0 1.0"/>
      <mass value="10000"/>
      <inertia ixx="10000" ixy="0.0" ixz="0.0" iyy="10000" iyz="0.0" izz="10000"/>
    </inertial>
  </link>
  <link name="frame_6">
    <collision>
      <origin rpy="0 0 0" xyz="1.0 -1.0 1.0"/>
      <geometry>
        <cylinder length="2" radius="0.02"/>
      </geometry>
    </collision>
    <visual>
      <origin rpy="0 0 0" xyz="1.0 -1.0 1.0"/>
      <geometry>
        <cylinder length="2" radius="0.02"/>
      </geometry>
      <material name="orange"/>
    </visual>
    <inertial>
      <origin rpy="0 0 0" xyz="1.0 -1.0 1.0"/>
      <mass value="10000"/>
      <inertia ixx="10000" ixy="0.0" ixz="0.0" iyy="10000" iyz="0.0" izz="10000"/>
    </inertial>
  </link>
  <link name="frame_7">
    <collision>
      <origin rpy="0 -1.5707963267948966 0" xyz="0 1.0 0"/>
      <geometry>
        <cylinder length="2" radius="0.02"/>
      </geometry>
    </collision>
    <visual>
      <origin rpy="0 -1.5707963267948966 0" xyz="0 1.0 0"/>
      <geometry>
        <cylinder length="2" radius="0.02"/>
      </geometry>
      <material name="orange"/>
    </visual>
    <inertial>
      <origin rpy="0 -1.5707963267948966 0" xyz="0 1.0 1.0"/>
      <mass value="10000"/>
      <inertia ixx="10000" ixy="0.0" ixz="0.0" iyy="10000" iyz="0.0" izz="10000"/>
    </inertial>
  </link>
  <link name="frame_8">
    <collision>
      <origin rpy="0 -1.5707963267948966 0" xyz="1.0 0 0"/>
      <geometry>
        <cylinder length="2" radius="0.02"/>
      </geometry>
    </collision>
    <visual>
      <origin rpy="-1.5707963267948966 0 0" xyz="1.0 0 0"/>
      <geometry>
        <cylinder length="2" radius="0.02"/>
      </geometry>
      <material name="orange"/>
    </visual>
    <inertial>
      <origin rpy="0 -1.5707963267948966 0" xyz="1.0 0 0"/>
      <mass value="10000"/>
      <inertia ixx="10000" ixy="0.0" ixz="0.0" iyy="10000" iyz="0.0" izz="10000"/>
    </inertial>
  </link>
  <link name="frame_9">
    <collision>
      <origin rpy="0 -1.5707963267948966 0" xyz="1.0 0 2"/>
      <geometry>
        <cylinder length="2" radius="0.02"/>
      </geometry>
    </collision>
    <visual>
      <origin rpy="-1.5707963267948966 0 0" xyz="1.0 0 2"/>
      <geometry>
        <cylinder length="2" radius="0.02"/>
      </geometry>
      <material name="orange"/>
    </visual>
    <inertial>
      <origin rpy="0 -1.5707963267948966 0" xyz="1.0 0 2"/>
      <mass value="10000"/>
      <inertia ixx="10000" ixy="0.0" ixz="0.0" iyy="10000" iyz="0.0" izz="10000"/>
    </inertial>
  </link>
  <link name="frame_10">
    <collision>
      <origin rpy="0 -1.5707963267948966 0" xyz="0 1.0 2"/>
      <geometry>
        <cylinder length="2" radius="0.02"/>
      </geometry>
    </collision>
    <visual>
      <origin rpy="0 -1.5707963267948966 0" xyz="0 1.0 2"/>
      <geometry>
        <cylinder length="2" radius="0.02"/>
      </geometry>
      <material name="orange"/>
    </visual>
    <inertial>
      <origin rpy="0 -1.5707963267948966 0" xyz="0 1.0 2"/>
      <mass value="10000"/>
      <inertia ixx="10000" ixy="0.0" ixz="0.0" iyy="10000" iyz="0.0" izz="10000"/>
    </inertial>
  </link>
  <link name="frame_11">
    <collision>
      <origin rpy="1.5707963267948966 0 0" xyz="-1.0 0 2"/>
      <geometry>
        <cylinder length="2" radius="0.02"/>
      </geometry>
    </collision>
    <visual>
      <origin rpy="1.5707963267948966 0 0" xyz="-1.0 0 2"/>
      <geometry>
        <cylinder length="2" radius="0.02"/>
      </geometry>
      <material name="orange"/>
    </visual>
    <inertial>
      <origin rpy="1.5707963267948966 0 0" xyz="-1.0 0 2"/>
      <mass value="10000"/>
      <inertia ixx="10000" ixy="0.0" ixz="0.0" iyy="10000" iyz="0.0" izz="10000"/>
    </inertial>
  </link>
  <link name="frame_12">
    <collision>
      <origin rpy="0 1.5707963267948966 0" xyz="0 -1.0 2"/>
      <geometry>
        <cylinder length="2" radius="0.02"/>
      </geometry>
    </collision>
    <visual>
      <origin rpy="0 1.5707963267948966 0" xyz="0 -1.0 2"/>
      <geometry>
        <cylinder length="2" radius="0.02"/>
      </geometry>
      <material name="orange"/>
    </visual>
    <inertial>
      <origin rpy="0 1.5707963267948966 0" xyz="0 -1.0 2"/>
      <mass value="10000"/>
      <inertia ixx="10000" ixy="0.0" ixz="0.0" iyy="10000" iyz="0.0" izz="10000"/>
    </inertial>
  </link>
  <link name="platform">
    <collision>
      <origin rpy="0 0 0" xyz="0.3 0.3 0.5"/>
      <geometry>
        <box size="0.3 0.3 0.3"/>
      </geometry>
    </collision>
    <visual>
      <origin rpy="0 0 0" xyz="0.3 0.3 0.5"/>
      <geometry>
        <box size="0.3 0.3 0.3"/>
      </geometry>
      <material name="red"/>
    </visual>
    <inertial>
      <origin rpy="0 0 0" xyz="0.3 0.3 0.5"/>
      <mass value="5"/>
      <inertia ixx="0.33" ixy="0" ixz="0" iyy="0.33" iyz="0" izz="0.33"/>
    </inertial>
  </link>
  <joint name="fixed12" type="fixed">
    <parent link="frame_11"/>
    <child link="frame_12"/>
  </joint>
  <joint name="fixed11" type="fixed">
    <parent link="frame_10"/>
    <child link="frame_11"/>
  </joint>
  <joint name="fixed10" type="fixed">
    <parent link="frame_9"/>
    <child link="frame_10"/>
  </joint>
  <joint name="fixed9" type="fixed">
    <parent link="frame_8"/>
    <child link="frame_9"/>
  </joint>
  <joint name="fixed8" type="fixed">
    <parent link="frame_7"/>
    <child link="frame_8"/>
  </joint>
  <joint name="fixed7" type="fixed">
    <parent link="frame_6"/>
    <child link="frame_7"/>
  </joint>
  <joint name="fixed6" type="fixed">
    <parent link="frame_5"/>
    <child link="frame_6"/>
  </joint>
  <joint name="fixed5" type="fixed">
    <parent link="frame_4"/>
    <child link="frame_5"/>
  </joint>
  <joint name="fixed4" type="fixed">
    <parent link="frame_3"/>
    <child link="frame_4"/>
  </joint>
  <joint name="fixed3" type="fixed">
    <parent link="frame_2"/>
    <child link="frame_3"/>
  </joint>
  <joint name="fixed2" type="fixed">
    <parent link="frame_1"/>
    <child link="frame_2"/>
  </joint>
  <!-- <xacro:loop2 links_qty="7" /> -->
  <!--
<joint name="platform_frame_fixed$" type="fixed">
  <parent link="frame_1" />
  <child link="platform" />
</joint> -->
  <!-- Camera -->
  <!--
  <link name="camera_link">
    <collision>
      <origin xyz="0 0 0" rpy="0 0 0" />
      <geometry>
        <box size="${camera_link} ${camera_link} ${camera_link}" />
      </geometry>
    </collision>

    <visual>
      <origin xyz="0 0 0" rpy="0 0 0" />
      <geometry>
        <box size="${camera_link} ${camera_link} ${camera_link}" />
      </geometry>
      <material name="red" />
    </visual>

    <inertial>
      <mass value="1e-5" />
      <origin xyz="0 0 0" rpy="0 0 0" />
      <inertia ixx="1e-6" ixy="0" ixz="0" iyy="1e-6" iyz="0" izz="1e-6" />
    </inertial>
  </link>

  <link name="camera_link_optical"></link>
  -->
  <!--

  <transmission name="lift_transmission">
    <type>transmission_interface/SimpleTransmission</type>
    <joint name="cable0">
        <hardwareInterface>PositionJointInterface</hardwareInterface>
    </joint>  
    <actuator name="lift_motor_0">
        <hardwareInterface>PositionJointInterface</hardwareInterface>
        <mechanicalReduction>1</mechanicalReduction>
    </actuator>
  </transmission>
  <transmission name="lift_transmission_1">
    <type>transmission_interface/SimpleTransmission</type>
    <joint name="cable1">
        <hardwareInterface>PositionJointInterface</hardwareInterface>
    </joint>  
    <actuator name="lift_motor_1">
        <hardwareInterface>PositionJointInterface</hardwareInterface>
        <mechanicalReduction>1</mechanicalReduction>
    </actuator>
  </transmission>
  <transmission name="lift_transmission_2">
    <type>transmission_interface/SimpleTransmission</type>
    <joint name="cable2">
        <hardwareInterface>PositionJointInterface</hardwareInterface>
    </joint>  
    <actuator name="lift_motor_2">
        <hardwareInterface>PositionJointInterface</hardwareInterface>
        <mechanicalReduction>1</mechanicalReduction>
    </actuator>
  </transmission>
  <transmission name="lift_transmission_3">
    <type>transmission_interface/SimpleTransmission</type>
    <joint name="cable3">
        <hardwareInterface>PositionJointInterface</hardwareInterface>
    </joint>  
    <actuator name="lift_motor_3">
        <hardwareInterface>PositionJointInterface</hardwareInterface>
        <mechanicalReduction>1</mechanicalReduction>
    </actuator>
  </transmission>
  <transmission name="lift_transmission_4">
    <type>transmission_interface/SimpleTransmission</type>
    <joint name="cable4">
        <hardwareInterface>PositionJointInterface</hardwareInterface>
    </joint>  
    <actuator name="lift_motor_4">
        <hardwareInterface>PositionJointInterface</hardwareInterface>
        <mechanicalReduction>1</mechanicalReduction>
    </actuator>
  </transmission>
  <transmission name="lift_transmission_5">
    <type>transmission_interface/SimpleTransmission</type>
    <joint name="cable5">
        <hardwareInterface>PositionJointInterface</hardwareInterface>
    </joint>  
    <actuator name="lift_motor_5">
        <hardwareInterface>PositionJointInterface</hardwareInterface>
        <mechanicalReduction>1</mechanicalReduction>
    </actuator>
  </transmission>
  <transmission name="lift_transmission_6">
    <type>transmission_interface/SimpleTransmission</type>
    <joint name="cable6">
        <hardwareInterface>PositionJointInterface</hardwareInterface>
    </joint>  
    <actuator name="lift_motor_6">
        <hardwareInterface>PositionJointInterface</hardwareInterface>
        <mechanicalReduction>1</mechanicalReduction>
    </actuator>
  </transmission>
  <transmission name="lift_transmission_7">
    <type>transmission_interface/SimpleTransmission</type>
    <joint name="cable7">
        <hardwareInterface>PositionJointInterface</hardwareInterface>
    </joint>  
    <actuator name="lift_motor_7">
        <hardwareInterface>PositionJointInterface</hardwareInterface>
        <mechanicalReduction>1</mechanicalReduction>
    </actuator>
  </transmission>
-->
</robot>

